{
  "stats": {
    "suites": 0,
    "tests": 1,
    "passes": 0,
    "pending": 0,
    "failures": 1,
    "start": "2020-05-06T08:36:46.243Z",
    "end": "2020-05-06T08:36:46.495Z",
    "duration": 252,
    "testsRegistered": 1,
    "passPercent": 0,
    "pendingPercent": 0,
    "other": 0,
    "hasOther": false,
    "skipped": 0,
    "hasSkipped": false
  },
  "results": [
    {
      "uuid": "f9d82b4d-39a3-4268-8665-5e7d527c3f82",
      "title": "",
      "fullFile": "",
      "file": "",
      "beforeHooks": [],
      "afterHooks": [],
      "tests": [
        {
          "title": "An uncaught error was detected outside of a test",
          "fullTitle": " An uncaught error was detected outside of a test",
          "timedOut": null,
          "duration": 230,
          "state": "failed",
          "speed": null,
          "pass": false,
          "fail": true,
          "pending": false,
          "context": null,
          "code": "throw err;",
          "err": {
            "message": "Uncaught CypressError: Cannot call \"cy.task()\" outside a running test.\n\nThis usually happens when you accidentally write commands outside an it(...) test.\n\nIf that is the case, just move these commands inside an it(...) test.\n\nCheck your test file for errors.\n\nhttps://on.cypress.io/cannot-execute-commands-outside-test\n\nThis error originated from your test code, not from Cypress.\n\nWhen Cypress detects uncaught errors originating from your test code it will automatically fail the current test.\n\nCypress could not associate this error to any specific test.\n\nWe dynamically generated a new test to display this failure.",
            "estack": "Uncaught CypressError: Cannot call \"cy.task()\" outside a running test.\n\nThis usually happens when you accidentally write commands outside an it(...) test.\n\nIf that is the case, just move these commands inside an it(...) test.\n\nCheck your test file for errors.\n\nhttps://on.cypress.io/cannot-execute-commands-outside-test\n\nThis error originated from your test code, not from Cypress.\n\nWhen Cypress detects uncaught errors originating from your test code it will automatically fail the current test.\n\nCypress could not associate this error to any specific test.\n\nWe dynamically generated a new test to display this failure.\n    at Object.cypressErr (http://localhost:62483/__cypress/runner/cypress_runner.js:85348:11)\n    at Object.throwErr (http://localhost:62483/__cypress/runner/cypress_runner.js:85303:18)\n    at Object.throwErrByPath (http://localhost:62483/__cypress/runner/cypress_runner.js:85335:17)\n    at Object.ensureRunnable (http://localhost:62483/__cypress/runner/cypress_runner.js:76541:21)\n    at Object.cy.(anonymous function) [as task] (http://localhost:62483/__cypress/runner/cypress_runner.js:80261:17)",
            "diff": null
          },
          "uuid": "5a9b0b9f-91e9-443e-a15b-cc88c456a59b",
          "parentUUID": "f9d82b4d-39a3-4268-8665-5e7d527c3f82",
          "isHook": false,
          "skipped": false
        }
      ],
      "suites": [],
      "passes": [],
      "failures": [
        "5a9b0b9f-91e9-443e-a15b-cc88c456a59b"
      ],
      "pending": [],
      "skipped": [],
      "duration": 230,
      "root": true,
      "rootEmpty": false,
      "_timeout": 2000
    }
  ],
  "meta": {
    "mocha": {
      "version": "6.2.2"
    },
    "mochawesome": {
      "options": {
        "quiet": false,
        "reportFilename": "mochawesome",
        "saveHtml": false,
        "saveJson": true,
        "consoleReporter": "spec",
        "useInlineDiffs": false
      },
      "version": "4.1.0"
    },
    "marge": {
      "options": {
        "id": "default",
        "reportDir": "cypress/reports/mochawesome",
        "overwrite": false,
        "html": false,
        "json": true
      },
      "version": "4.0.1"
    }
  }
}